Workbook
Name OtherLeaveType: #REF!

Sheet Master
A2: Consultant Name: | B2: Anonymous
A3: Post Title: | B3: Consultant in Radiology
A4: Annual Leave Year Dates: | B4: 45898 | D4: to | E4: 46262
A6: Job plan review date: | B6: 46235
A8: Job plan 1 | D8: Job plan 2
A9: From: | B9: =B4 -> 45898 | D9: From: | E9: =B10 -> 46235
A10: To: | B10: =B6 -> 46235 | D10: To: | E10: =E4+1 -> 46263
A11: Number of days: | B11: =B10-B9 -> 337 | D11: Number of days: | E11: =E10-E9 -> 28
A12: Job Plan DCC: | B12: 5.91 | D12: Job Plan DCC: | E12: 5.91
A13: Job Plan SPA: | B13: 2.56 | D13: Job Plan SPA: | E13: 2.56
A14: Job Plan Total PA: | B14: =B12+B13 -> 8.47 | D14: Job Plan Total PA: | E14: =E12+E13 -> 8.47 | G14: Annual Leave entitlement (Inc. B/H): | J14: =Sheet1!D10 -> 291.368
J15: DCC | K15: SPA
A16: Annual Leave accrued: | B16: =J14*(B11/365) -> 269.01648 | D16: Annual Leave accrued: | E16: =J14*(E11/365) -> 22.351518 | G16: Annual Leave DCC/SPA: | J16: =B17+E17 -> 203.304 | K16: =B18+E18 -> 88.064
A17: DCC | B17: =B16*(B12/B14) -> 187.70808 | D17: DCC | E17: =E16*(E12/E14) -> 15.595923 | G17: Carry Forward: | J17: 41.25
A18: SPA | B18: =B16*(B13/B14) -> 81.308405 | D18: SPA | E18: =E16*(E13/E14) -> 6.7555945 | G18: Total Leave entitlement (Hours): | J18: =J16+J17 -> 244.554 | K18: =K16+K17 -> 88.064
A20: Leave taken
A21: Mondays | B21: =COUNTA('Annual Leave Log'!C16:C43)+COUNTA('Annual Leave Log'!C14:C75) -> 24 | G21: DCC | H21: SPA
A22: Tuesdays | B22: =COUNTA('Annual Leave Log'!E16:E43)+COUNTA('Annual Leave Log'!E14:E75) -> 24 | E22: Leave Taken: | G22: ='Annual Leave Log'!M46+'Annual Leave Log'!M81 -> 229.5 | H22: ='Annual Leave Log'!N46+'Annual Leave Log'!N81 -> 18
A23: Wednesdays | B23: =COUNTA('Annual Leave Log'!G16:G43)+COUNTA('Annual Leave Log'!G14:G75) -> 24
A24: Thursdays | B24: =COUNTA('Annual Leave Log'!I16:I43)+COUNTA('Annual Leave Log'!I14:I75) -> 2 | E24: Leave Remaining: | G24: =J18-G22 -> 15.054 | H24: =K18-H22 -> 70.064
A25: Fridays | B25: =COUNTA('Annual Leave Log'!K16:K43)+COUNTA('Annual Leave Log'!K14:K75) -> 2

Sheet Annual Leave Log
A2: NAME | B2: =Master!B2 -> Anonymous | E2: POST TITLE | G2: =Master!B3 -> Consultant in Radiology | K2: A/L YEAR DATES | M2: =Master!B4 -> 45898 | N2: =Master!E4 -> 46262
A5: Annual Leave dates (Job plan 1)
A6: From | B6: To | C6: Monday | E6: Tuesday | G6: Wednesday | I6: Thursday | K6: Friday | M6: DCC Hours | N6: SPA Hours
C7: DCC | D7: SPA | E7: DCC | F7: SPA | G7: DCC | H7: SPA | I7: DCC | J7: SPA | K7: DCC | L7: SPA
A8: Standard Job plan hours: | C8: 8 | D8: 0.5 | E8: 8 | F8: 2 | G8: 4.5 | H8: 1.5 | M8: =C8+E8+G8+I8+K8+3 -> 23.5 | N8: =D8+F8+H8+J8+L8+4 -> 8
A9: 46016 | B9: (Bank Holiday) | I9: 0 | J9: 0 | M9: =C9+E9+G9+I9+K9 -> 0 | N9: =D9+F9+H9+J9+L9 -> 0
A10: 46017 | B10: (Bank Holiday) | K10: 0 | L10: 0 | M10: =C10+E10+G10+I10+K10 -> 0 | N10: =D10+F10+H10+J10+L10 -> 0
A11: 46023 | B11: (Bank Holiday) | I11: 0 | J11: 0 | M11: =C11+E11+G11+I11+K11 -> 0 | N11: =D11+F11+H11+J11+L11 -> 0
A12: 46115 | B12: (Bank Holiday) | K12: 0 | L12: 0 | M12: =C12+E12+G12+I12+K12 -> 0 | N12: =D12+F12+H12+J12+L12 -> 0
A13: 46118 | B13: (Bank Holiday) | C13: 8 | D13: 0.5 | M13: =C13+E13+G13+I13+K13 -> 8 | N13: =D13+F13+H13+J13+L13 -> 0.5
A14: 46146 | B14: (Bank Holiday) | C14: 0 | D14: 0 | M14: =C14+E14+G14+I14+K14 -> 0 | N14: =D14+F14+H14+J14+L14 -> 0 | P14: on-call
A15: 46167 | B15: (Bank Holiday) | C15: 8 | D15: 0.5 | M15: =C15+E15+G15+I15+K15 -> 8 | N15: =D15+F15+H15+J15+L15 -> 0.5
A16: 45950 | C16: 8 | D16: 0.5 | M16: =C16+E16+G16+I16+K16 -> 8 | N16: =D16+F16+H16+J16+L16 -> 0.5
A17: 45951 | E17: 8 | F17: 2 | M17: =C17+E17+G17+I17+K17 -> 8 | N17: =D17+F17+H17+J17+L17 -> 2
A18: 45952 | G18: 4.5 | H18: 1.5 | M18: =C18+E18+G18+I18+K18 -> 4.5 | N18: =D18+F18+H18+J18+L18 -> 1.5
A19: 45957 | C19: 6.5 | M19: =C19+E19+G19+I19+K19 -> 6.5 | N19: =D19+F19+H19+J19+L19 -> 0
A20: 45999 | C20: 8 | D20: 0 | M20: =C20+E20+G20+I20+K20 -> 8 | N20: =D20+F20+H20+J20+L20 -> 0
A21: 38695 | E21: 8 | F21: 2 | M21: =C21+E21+G21+I21+K21 -> 8 | N21: =D21+F21+H21+J21+L21 -> 2
A22: 46001 | G22: 4.5 | H22: 1.5 | M22: =C22+E22+G22+I22+K22 -> 4.5 | N22: =D22+F22+H22+J22+L22 -> 1.5
A23: 46006 | C23: 8 | D23: 0.5 | M23: =C23+E23+G23+I23+K23 -> 8 | N23: =D23+F23+H23+J23+L23 -> 0.5
A24: 46007 | E24: 8 | F24: 2 | M24: =C24+E24+G24+I24+K24 -> 8 | N24: =D24+F24+H24+J24+L24 -> 2
A25: 46008 | G25: 4.5 | H25: 1.5 | M25: =C25+E25+G25+I25+K25 -> 4.5 | N25: =D25+F25+H25+J25+L25 -> 1.5
A26: 46021 | E26: 8 | F26: 0 | M26: =C26+E26+G26+I26+K26 -> 8 | N26: =D26+F26+H26+J26+L26 -> 0
A27: 46022 | G27: 4 | H27: 0 | M27: =C27+E27+G27+I27+K27 -> 4 | N27: =D27+F27+H27+J27+L27 -> 0
A28: 38806 | C28: 7.5 | D28: 0 | M28: =C28+E28+G28+I28+K28 -> 7.5 | N28: =D28+F28+H28+J28+L28 -> 0
A29: 46112 | E29: 4 | F29: 0 | M29: =C29+E29+G29+I29+K29 -> 4 | N29: =D29+F29+H29+J29+L29 -> 0
A30: 46113 | G30: 4.5 | H30: 0 | M30: =C30+E30+G30+I30+K30 -> 4.5 | N30: =D30+F30+H30+J30+L30 -> 0
A31: 46119 | E31: 5 | F31: 0 | M31: =C31+E31+G31+I31+K31 -> 5 | N31: =D31+F31+H31+J31+L31 -> 0
A32: 46120 | G32: 4.5 | H32: 0 | M32: =C32+E32+G32+I32+K32 -> 4.5 | N32: =D32+F32+H32+J32+L32 -> 0
A33: 46202 | C33: 6 | D33: 0 | M33: =C33+E33+G33+I33+K33 -> 6 | N33: =D33+F33+H33+J33+L33 -> 0
A34: 46203 | E34: 4 | F34: 0 | M34: =C34+E34+G34+I34+K34 -> 4 | N34: =D34+F34+H34+J34+L34 -> 0
A35: 46204 | G35: 3.5 | M35: =C35+E35+G35+I35+K35 -> 3.5 | N35: =D35+F35+H35+J35+L35 -> 0
A36: 46209 | C36: 6 | D36: 0 | M36: =C36+E36+G36+I36+K36 -> 6 | N36: =D36+F36+H36+J36+L36 -> 0
A37: 46210 | E37: 4 | F37: 0 | M37: =C37+E37+G37+I37+K37 -> 4 | N37: =D37+F37+H37+J37+L37 -> 0
A38: 46211 | G38: 4.5 | H38: 0 | M38: =C38+E38+G38+I38+K38 -> 4.5 | N38: =D38+F38+H38+J38+L38 -> 0
A39: 46216 | C39: 6 | D39: 0 | M39: =C39+E39+G39+I39+K39 -> 6 | N39: =D39+F39+H39+J39+L39 -> 0
A40: 46217 | E40: 8 | F40: 0 | M40: =C40+E40+G40+I40+K40 -> 8 | N40: =D40+F40+H40+J40+L40 -> 0
A41: 46218 | G41: 4.5 | H41: 0 | M41: =C41+E41+G41+I41+K41 -> 4.5 | N41: =D41+F41+H41+J41+L41 -> 0
M42: =C42+E42+G42+I42+K42 -> 0 | N42: =D42+F42+H42+J42+L42 -> 0
M43: =C43+E43+G43+I43+K43 -> 0 | N43: =D43+F43+H43+J43+L43 -> 0
...

Sheet Sheet1
C2: Days | D2: Hours
B3: Basic | C3: 30 | D3: =6*8*5 -> 240
B4: Stat Days | C4: 2 | D4: =2*8 -> 16
B5: Seniority (>7 yrs) | C5: 2 | D5: 16
B6: Hospital R&R | C6: 2 | D6: =2*8 -> 16
B7: Bank Hols | C7: 7 | D7: =8*C7 -> 56
B8: Total Hours: | D8: =SUM(D3:D7) -> 344
B10: Pro-rata: | D10: =D8*(MIN(Master!B14,10)/10) -> 291.368
